Workbook
Name Master2026StatusList: 'Data Validation'!$A$1:$A$19

Sheet Summary
A2: Geo | B2: India | G2: Geo | H2: USA
A3: Status | B3: (Multiple Items) | G3: Status | H3: Offered
A4: Position Open Date | B4: (All) | G4: Position Open Date | H4: (All)
A6: No. of Position | G6: No. of Positions
A7: 2
A11: Geo | B11: India | G11: Geo | H11: USA
A12: Status | B12: Offered | G12: Status | H12: Offered
A13: Position Open Date | B13: (All) | G13: Position Open Date | H13: (All)
A15: No. of Offered | G15: No. of Offered
A16: 2
A20: Geo | B20: India | G20: Geo | H20: USA
A21: Status | B21: Joined | G21: Status | H21: Joined
A22: Position Open Date | B22: (All) | G22: Position Open Date | H22: (All)
A24: Joining YTD | G24: Joining YTD
A25: 63 | G25: 38
A30: Geo | B30: India | G30: Geo | H30: USA
A31: Status | B31: JD Pending | G31: Status | H31: JD Pending
A32: Position Open Date | B32: (All) | G32: Position Open Date | H32: (All)
A34: JD Pending | G34: JD Pending
A35: 1 | G35: 1
A39: Geo | B39: India | G39: Geo | H39: USA
A40: Status | B40: Position Freezed | G40: Status | H40: Position Freezed
A41: Position Open Date | B41: (All) | G41: Position Open Date | H41: (All)
A43: Suspended | G43: Suspended
A44: 20 | G44: 6
A48: Geo | B48: USA
A49: Status | B49: Joined
A51: Count of Department | D51: Quarter Joining
A52: Squads | B52: Department | C52: Full-Time/Consultant | D52: Q1 | E52: Q2 | F52: Q3 | G52: Grand Total
A53: Account | B53: Account Galaxy | C53: Full-time | F53: 1 | G53: 1
A54: Account | B54: Engineering | C54: Full-time | E54: 1 | G54: 1
A55: Account | B55: PS | C55: Full-time | F55: 1 | G55: 1
A56: DevOps | B56: DevOps | C56: Consultant | E56: 1 | G56: 1
A57: DevOps | B57: DevOps | C57: Full-time | D57: 1 | F57: 1 | G57: 2
A58: DevOps | B58: Technology | C58: Full-time | F58: 1 | G58: 1
A59: Digital | B59: Engineering | C59: Full-time | E59: 1 | G59: 1
A60: Finance | B60: Finance | C60: Full-time | F60: 1 | G60: 1
A61: GTM | B61: Support | D61: 1 | G61: 1
A62: HR | B62: HR | C62: Full-time | D62: 1 | E62: 1 | G62: 2
A63: Infosec | B63: Infosec | C63: Full-time | D63: 1 | E63: 1 | G63: 2
...

Sheet Open Reqs- INDIA
A1: Geo | B1: India
A2: Position Open Date | B2: (All)
A5: Squads | B5: Department | C5: Hiring Location | D5: Full-Time/ Consultant | E5: Positions | F5: New/ Replacement | G5: Replaced Employee Name | H5: Status | I5: Aging (Days) | J5: Comments
A6: Finance | B6: Finance | C6: Chennai | D6: Full-time | E6: NetSuite Implementation Expert | F6: New | G6: (blank) | H6: JD Pending | I6: 7 | J6: JD pending with Dharani

Sheet Open Reqs - USA
A1: Geo | B1: USA
A2: Position Open Date | B2: (All)
A5: Squads | B5: Department | C5: Hiring Location | D5: Full-Time/ Consultant | E5: Positions | F5: New/ Replacement | G5: Replaced Employee Name | H5: Aging (Days) | I5: Comments | J5: Status

Sheet Offers -INDIA
A1: Geo | B1: India
A2: Position Open Date | B2: (All)
A5: Squads | B5: Hiring Location | C5: Positions | D5: Full-Time/ Consultant | E5: Date Offered | F5: Joining Date | G5: Status | H5: Offered Candidates | I5: RAG Status | J5: Buddy - Onboarding | K5: Back-up Plans
A6: Support | B6: Remote | C6: Production Support Engineer ( Payments) | D6: Full-time | E6: 46302 | F6: 46357 | G6: Offered | H6: Mahendra Kolate | I6: Amber | J6: (blank) | K6: Sourcing
A7: Technology | B7: Chennai | C7: Junior IT Admin | D7: Full-time | E7: 46314 | F7: 46329 | G7: Offered | H7: Athiban Eswar | I7: Green | J7: Senthil | K7: Final select

Sheet Offers-USA
A1: Geo | B1: USA
A2: Position Open Date | B2: (All)
A5: Squads | B5: Hiring Location | C5: Positions | D5: Full-Time/ Consultant | E5: Date Offered | F5: Joining Date | G5: Status | H5: Offered Candidates | I5: Buddy - Onboarding | J5: Highest Qualification Degree

Sheet Joining -INDIA
A2: Geo | B2: (Multiple Items)
A3: Position Open Date | B3: (All)
A5: Squads | B5: Department | C5: Hiring Location | D5: Positions | E5: Full-Time/Consultant | F5: Joining Date | G5: Status | H5: Offered Candidates
A6: Account | B6: Engineering | C6: Chennai | D6: Compliance - AI Developer | E6: Full-time | F6: 46104 | G6: Joined | H6: Vaishnavi
A7: Account | B7: Engineering | C7: Chennai | D7: Full-stack Engineer | E7: Full-time | F7: 46162 | G7: Joined | H7: Kalirajan
A8: Account | B8: Product | C8: Chennai | D8: Product Manager - Deposits & VA | E8: Full-time | F8: 46104 | G8: Joined | H8: Arivumani N
A9: Account | B9: Product | C9: Pune | D9: Product Manager - VA | E9: Full-time | F9: 46140 | G9: Joined | H9: Dhawal
A10: Account | B10: QA | C10: Chennai | D10: QA Analyst | E10: Full-time | F10: 46083 | G10: Joined | H10: Keerthika
A11: Account | B11: QA | C11: Chennai | D11: QA Analyst | E11: Full-time | F11: 46093 | G11: Joined | H11: Nikhil C Karanam
A12: Account | B12: QA | C12: Chennai | D12: QA Analyst | E12: Full-time | F12: 46132 | G12: Joined | H12: Arul Anand
A13: DevOps | B13: DevOps | C13: Chennai | D13: DevOps Engineer | E13: Full-time | F13: 46181 | G13: Joined | H13: Deepakraj J
A14: DevOps | B14: DevOps | C14: Chennai | D14: DevOps Engineer | E14: Full-time | F14: 46086 | G14: Joined | H14: Senthil R
A15: DevOps | B15: DevOps | C15: Chennai | D15: Trainee DevOps Engineer | E15: Full-time | F15: 46195 | G15: Joined | H15: Prasanna
A16: DevOps | B16: DevOps | C16: Pune | D16: DevOps Engineer | E16: Full-time | F16: 46188 | G16: Joined | H16: Faheem
A17: Digital | B17: Engineering | C17: Chennai | D17: Backend Developer | E17: Full-time | F17: 46239 | G17: Joined | H17: Thameenansari
... A68: Trade | B68: QA | C68: Chennai | D68: QA Analyst | E68: Full-time | F68: 46160 | G68: Joined | H68: Nirmal

Sheet Joining -USA
A3: Geo | B3: USA
A4: Position Open Date | B4: (All)
A7: Squads | B7: Department | C7: Hiring Location | D7: Positions | E7: Full-Time/Consultant | F7: Joining Date | G7: Status | H7: Offered Candidates
A8: DevOps | B8: DevOps | C8: Charlotte | D8: Director of Infrastructure | E8: Full-time | F8: 46057 | G8: Joined | H8: Manoj
A9: DevOps | B9: DevOps | C9: Charlotte | D9: IT Admin Consultant | E9: Consultant | F9: 46181 | G9: Joined | H9: Tejasri Balusu
A10: DevOps | B10: DevOps | C10: Charlotte | D10: Associate AI Engineer_DecOps | E10: Full-time | F10: 46237 | G10: Joined | H10: Bladen Martin
A11: DevOps | B11: Technology | C11: Charlotte | D11: Data Architect | E11: Full-time | F11: 46226 | G11: Joined | H11: Narayanan Sundaram
A12: Finance | B12: Finance | C12: Charlotte | D12: Chief Finance Officer | E12: Full-time | F12: 46314 | G12: Joined | H12: Jack McCullen
A13: Finance | B13: Finance | C13: Charlotte | D13: Commercial Contracts Manager | E13: Full-time | F13: 46216 | G13: Joined | H13: Cystal Goodwin
A14: Infosec | B14: Infosec | C14: Charlotte | D14: CISO (Change of Role) | E14: Full-time | F14: 46055 | G14: Joined | H14: Supro
A15: Infosec | B15: Infosec | C15: Charlotte | D15: Associate AI Engineer _InfoSec | E15: Full-time | F15: 46169 | G15: Joined | H15: Shubham Bhojwani
A16: Payments | B16: Engineering | C16: Charlotte | D16: Enterprise Architect | E16: Full-time | F16: 46132 | G16: Joined | H16: Lakshminarayan
A17: Payments | B17: Engineering | C17: Charlotte | D17: Lead Software Engineer - ACH | E17: Full-time | F17: 46224 | G17: Joined | H17: Alka Lakhote
A18: Payments | B18: Product | C18: Charlotte | D18: Product Owner (Change of Role) | E18: Full-time | F18: 46042 | G18: Joined | H18: Melissa
A19: Payments | B19: Payments | C19: Charlotte | D19: AI Developer | E19: Full-time | F19: 46160 | G19: Joined | H19: Aditya Khandare
... A45: Digital | B45: Engineering | C45: Charlotte | D45: Associate AI Engineer_Digital Galaxy | E45: Full-time | F45: 46188 | G45: Joined | H45: Shubham Salonki

Sheet On Hold
A4: #VALUE!
A13: Geo | B13: USA
A14: Position Open Date | B14: (All)
A17: Squads | B17: Positions | C17: Full-Time/Consultant | D17: Replaced Employee Name | E17: New/Replacement | F17: Hiring Location | G17: Status
A18: DevOps | B18: SecOps - Enterprise Governance | C18: Full-time | D18: (blank) | E18: New | F18: Charlotte | G18: Suspended
B19: DevOps Engineer | C19: Full-time | D19: Prathamesh | E19: Replacement | F19: Charlotte | G19: Suspended
A20: PS | B20: Project Manager | C20: Full-time | D20: (blank) | E20: New | F20: Charlotte | G20: Suspended
A21: Account | B21: Solution Engineer | C21: Full-time | D21: (blank) | E21: New | F21: Charlotte | G21: Suspended
A22: GTM | B22: Marketing Trainee Associate | C22: Full-time | D22: (blank) | E22: New | F22: Charlotte | G22: Suspended
A23: AI | B23: Associate AI Engineer | C23: Full-time | D23: (blank) | E23: New | F23: Charlotte | G23: Suspended

Sheet Recruitment- Master
A1: Sr No | B1: Geo | C1: Practice | D1: Project | E1: Positions | F1: New/Replacement | G1: Full-Time/Consultant | H1: Hiring Location | I1: Position Open Date | J1: Todays Date | K1: Date Offered | L1: Joining Date | M1: Aging (Days) | N1: Position Offered | O1: Position Closed | P1: Status | Q1: Offered Candidates | R1: Remarks | S1: Recruiter Name | T1: Replaced Employee | U1: Remark
A2: 1 | B2: India | C2: Quality Assurance | D2: PS | E2: Lead Analyst | F2: Replacement | H2: Chennai | I2: 44971 | J2: 44987 | K2: 44987 | L2: 44991 | M2: =NETWORKDAYS(I2,J2) -> 13 | N2: =IF(K2="",0,NETWORKDAYS(I2,K2)) -> 13 | O2: =IF(L2="",0,NETWORKDAYS(I2,L2)) -> 15 | P2: Joined | R2: Deepak Joined on 6 Mar 23 | T2: Sudhir | U2: Sudhir replacement
A3: =A2+1 -> 2 | B3: USA | C3: Development | D3: Bank OS | E3: Senior Developer | F3: New | H3: USA | I3: 45093 | J3: 45182 | K3: 45141 | L3: 45166 | M3: =NETWORKDAYS(I3,J3) -> 64 | N3: =IF(K3="",0,NETWORKDAYS(I3,K3)) -> 35 | O3: =IF(L3="",0,NETWORKDAYS(I3,L3)) -> 52 | P3: Joined | R3: Sent an offer to Sangeetha and she accepted the offer. Joined August 28, 2023.
A4: =A3+1 -> 3 | B4: India | C4: Development | D4: Bank OS | E4: Senior Developer/Lead Developer | F4: New | H4: Chennai | I4: 45099 | J4: 45001 | M4: =NETWORKDAYS(I4,J4) -> -71 | N4: =IF(K4="",0,NETWORKDAYS(I4,K4)) -> 0 | O4: =IF(L4="",0,NETWORKDAYS(I4,L4)) -> 0 | P4: Suspended | T4: No need for Ganesh replacement | U4: No need for Ganesh replacement
A5: =A4+1 -> 4 | B5: India | C5: Development | D5: Bank OS | E5: Developer | F5: New | H5: Chennai | I5: 45139 | J5: 45182 | K5: 45182 | L5: 45202 | M5: =NETWORKDAYS(I5,J5) -> 32 | N5: =IF(K5="",0,NETWORKDAYS(I5,K5)) -> 32 | O5: =IF(L5="",0,NETWORKDAYS(I5,L5)) -> 46 | P5: Joined | R5: Vigneshwar accepted offer - 3rd Oct | T5: Keerthana is performing good now | U5: Keerthana is performing good now
A6: =A5+1 -> 5 | B6: India | C6: Quality Assurance | D6: FX | E6: Lead Analyst | F6: Replacement | H6: Chennai | I6: 44993 | J6: 45001 | K6: 45001 | L6: 45005 | M6: =NETWORKDAYS(I6,J6) -> 7 | N6: =IF(K6="",0,NETWORKDAYS(I6,K6)) -> 7 | O6: =IF(L6="",0,NETWORKDAYS(I6,L6)) -> 9 | P6: Joined | R6: Farooq Joined on 20 Mar 23 | T6: Priya | U6: Priya replacement
A7: =A6+1 -> 6 | B7: USA | C7: Development | D7: Bank OS | E7: Director of Payment Technology | F7: Replacement | H7: USA | I7: 45047 | J7: 45078 | K7: 45078 | L7: 45082 | M7: =NETWORKDAYS(I7,J7) -> 24 | N7: =IF(K7="",0,NETWORKDAYS(I7,K7)) -> 24 | O7: =IF(L7="",0,NETWORKDAYS(I7,L7)) -> 26 | P7: Joined | R7: Atul Choudhari accepted the offer and joined Finzly on June 5, 2023
A8: =A7+1 -> 7 | B8: India | C8: Quality Assurance | D8: Bank OS | E8: Automation | F8: New | H8: Chennai | I8: 45012 | J8: 45023 | K8: 45023 | L8: 45035 | M8: =NETWORKDAYS(I8,J8) -> 10 | N8: =IF(K8="",0,NETWORKDAYS(I8,K8)) -> 10 | O8: =IF(L8="",0,NETWORKDAYS(I8,L8)) -> 18 | P8: Joined | R8: Nagarajan Joined on 19th April
A9: =A8+1 -> 8 | B9: USA | C9: Professional Services | D9: PS | E9: Senior Business Analyst | F9: New | H9: USA | I9: 45047 | J9: 45112 | K9: 45089 | L9: 45096 | M9: =NETWORKDAYS(I9,J9) -> 48 | N9: =IF(K9="",0,NETWORKDAYS(I9,K9)) -> 31 | O9: =IF(L9="",0,NETWORKDAYS(I9,L9)) -> 36 | P9: Joined | R9: Pandiya Rajan started on June 19, 2023
A10: =A9+1 -> 9 | B10: India | C10: Development | D10: Cash OS | E10: Lead Engineer | F10: Replacement | H10: Chennai | I10: 45100 | J10: 45120 | K10: 45120 | L10: 45121 | M10: =NETWORKDAYS(I10,J10) -> 15 | N10: =IF(K10="",0,NETWORKDAYS(I10,K10)) -> 15 | O10: =IF(L10="",0,NETWORKDAYS(I10,L10)) -> 16 | P10: Joined | R10: Sagana Joined | T10: Sarayu/Sagana | U10: Sarayu/Sagana Replacement
A11: =A10+1 -> 10 | B11: India | C11: Development | D11: Cash OS | E11: Associate Developer | F11: Replacement | H11: Pune | I11: 45076 | J11: 45085 | K11: 45085 | L11: 45089 | M11: =NETWORKDAYS(I11,J11) -> 8 | N11: =IF(K11="",0,NETWORKDAYS(I11,K11)) -> 8 | O11: =IF(L11="",0,NETWORKDAYS(I11,L11)) -> 10 | P11: Joined | R11: Chetan DOJ -12th June | T11: Shubham terminated due to negative BGV | U11: Shubham terminated due to negative BGV
A12: =A11+1 -> 11 | B12: India | C12: Development | D12: PS | E12: Lead Developer | F12: Replacement | H12: Pune | I12: 44987 | J12: 45057 | K12: 45057 | L12: 45061 | M12: =NETWORKDAYS(I12,J12) -> 51 | N12: =IF(K12="",0,NETWORKDAYS(I12,K12)) -> 51 | O12: =IF(L12="",0,NETWORKDAYS(I12,L12)) -> 53 | P12: Joined | R12: Ravipratap joined - 15-May-23 | T12: Shriram replacement | U12: Shriram replacement
A13: =A12+1 -> 12 | B13: India | C13: Development | D13: Bank OS | E13: Lead Developer | F13: Replacement | H13: Pune | I13: 45100 | J13: 45112 | K13: 45112 | L13: 45117 | M13: =NETWORKDAYS(I13,J13) -> 9 | N13: =IF(K13="",0,NETWORKDAYS(I13,K13)) -> 9 | O13: =IF(L13="",0,NETWORKDAYS(I13,L13)) -> 12 | P13: Joined | R13: Prashant Arun Joined - 10th July 2023 | T13: Nilima P replacement | U13: Nilima P replacement
A14: =A13+1 -> 13 | B14: India | C14: Product | D14: Trade Finance | E14: Product Owner | F14: Replacement | H14: Chennai | I14: 45219 | J14: 45180 | K14: 45247 | M14: =NETWORKDAYS(I14,J14) -> -30 | N14: =IF(K14="",0,NETWORKDAYS(I14,K14)) -> 21 | O14: =IF(L14="",0,NETWORKDAYS(I14,L14)) -> 0 | P14: Suspended | R14: Mangesh Offer in approval | T14: Sathya | U14: Sathya
A15: =A14+1 -> 14 | B15: India | C15: Quality Assurance | D15: PS | E15: Lead Analyst | F15: Replacement | H15: Pune | I15: 45123 | J15: 45135 | K15: 45135 | L15: 45138 | M15: =NETWORKDAYS(I15,J15) -> 10 | N15: =IF(K15="",0,NETWORKDAYS(I15,K15)) -> 10 | O15: =IF(L15="",0,NETWORKDAYS(I15,L15)) -> 11 | P15: Joined | R15: Pravin Gurav joined 31st July | T15: Deepak Replacement | U15: Deepak Replacement
A16: =A15+1 -> 15 | B16: India | C16: Development | D16: PS | E16: Lead Developer | F16: Replacement | H16: Pune | I16: 45169 | J16: 45185 | K16: 45185 | L16: 45187 | M16: =NETWORKDAYS(I16,J16) -> 12 | N16: =IF(K16="",0,NETWORKDAYS(I16,K16)) -> 12 | O16: =IF(L16="",0,NETWORKDAYS(I16,L16)) -> 13 | P16: Joined | R16: Swapnil | T16: Vivek Honule Replacement | U16: Vivek Honule Replacement
A17: =A16+1 -> 16 | B17: India | C17: Operations | D17: Finance | E17: Accountant | F17: New | H17: Pune/Chennai | I17: 45133 | J17: 45158 | K17: 45158 | L17: 45202 | M17: =NETWORKDAYS(I17,J17) -> 18 | N17: =IF(K17="",0,NETWORKDAYS(I17,K17)) -> 18 | O17: =IF(L17="",0,NETWORKDAYS(I17,L17)) -> 50 | P17: Joined | R17: Chaitanya joined on 25th Sep 2023
A18: =A17+1 -> 17 | B18: USA | C18: Professional Services | D18: PS | E18: Senior Business Analyst | F18: New | H18: USA | I18: 45129 | J18: =TODAY() -> 46324 | K18: 45154 | L18: 45175 | M18: =NETWORKDAYS(I18,J18) -> 854 | N18: =IF(K18="",0,NETWORKDAYS(I18,K18)) -> 18 | O18: =IF(L18="",0,NETWORKDAYS(I18,L18)) -> 33 | P18: Joined | R18: Souvik started on October 5, 2023. Bala will start on October 10, 2023.
A19: =A18+1 -> 18 | B19: USA | C19: Professional Services | D19: PS | E19: Client Implementation Manager | F19: New | H19: USA | I19: 45184 | J19: 45175 | K19: 45155 | L19: 45175 | M19: =NETWORKDAYS(I19,J19) -> -8 | N19: =IF(K19="",0,NETWORKDAYS(I19,K19)) -> -22 | O19: =IF(L19="",0,NETWORKDAYS(I19,L19)) -> -8 | P19: Joined | R19: We have moved Rehman into this role, he was originally being considered for the Senior Business Analyst Role.
A20: =A19+1 -> 19 | B20: India | C20: Development | D20: Cash OS | E20: Lead Engineer | F20: Replacement | H20: Pune | I20: 45128 | J20: 45135 | K20: 45135 | L20: 45131 | M20: =NETWORKDAYS(I20,J20) -> 6 | N20: =IF(K20="",0,NETWORKDAYS(I20,K20)) -> 6 | O20: =IF(L20="",0,NETWORKDAYS(I20,L20)) -> 2 | P20: Joined | R20: Anupam joined 31st July | T20: Sagana Replacement | U20: Sagana Replacement
A21: =A20+1 -> 20 | B21: India | C21: Quality Assurance | D21: FX | E21: Automation | F21: New | H21: Chennai | I21: 45154 | J21: 45180 | K21: 45180 | L21: 45181 | M21: =NETWORKDAYS(I21,J21) -> 19 | N21: =IF(K21="",0,NETWORKDAYS(I21,K21)) -> 19 | O21: =IF(L21="",0,NETWORKDAYS(I21,L21)) -> 20 | P21: Joined | R21: Felvia P. Tentative joining - 11 September 2023
A22: =A21+1 -> 21 | B22: India | C22: Development | D22: FX | E22: Mid Developer | F22: New | H22: Chennai | I22: 45289 | J22: =TODAY() -> 46324 | K22: 45343 | L22: 45362 | M22: =NETWORKDAYS(I22,J22) -> 740 | N22: =IF(K22="",0,NETWORKDAYS(I22,K22)) -> 39 | O22: =IF(L22="",0,NETWORKDAYS(I22,L22)) -> 52 | P22: Temp Hold | S22: Sugan
A23: =A22+1 -> 22 | B23: India | C23: Customer Success | D23: Support | E23: Production Support | F23: New | H23: Pune | I23: 45159 | J23: 45175 | K23: 45175 | L23: 45176 | M23: =NETWORKDAYS(I23,J23) -> 13 | N23: =IF(K23="",0,NETWORKDAYS(I23,K23)) -> 13 | O23: =IF(L23="",0,NETWORKDAYS(I23,L23)) -> 14 | P23: Joined | R23: Dipak Patil joined 7th september 2023
A24: =A23+1 -> 23 | B24: India | C24: Customer Success | D24: Support | E24: Production Support | F24: New | H24: Chennai | I24: 45202 | J24: 45180 | K24: 45180 | L24: 45202 | M24: =NETWORKDAYS(I24,J24) -> -17 | N24: =IF(K24="",0,NETWORKDAYS(I24,K24)) -> -17 | O24: =IF(L24="",0,NETWORKDAYS(I24,L24)) -> 1 | P24: Joined | R24: Kapil joined
A25: =A24+1 -> 24 | B25: India | C25: Development | D25: PS | E25: Developer(BankOs) | F25: New | H25: Pune | I25: 45149 | J25: 45161 | K25: 45161 | L25: 45162 | M25: =NETWORKDAYS(I25,J25) -> 9 | N25: =IF(K25="",0,NETWORKDAYS(I25,K25)) -> 9 | O25: =IF(L25="",0,NETWORKDAYS(I25,L25)) -> 10 | P25: Joined | R25: Sanket DOJ- 25th August 2023
A26: =A25+1 -> 25 | B26: India | C26: Development | D26: PS | E26: Mid Developer(BankOs) | F26: New | H26: Pune | I26: 45149 | J26: 45161 | K26: 45161 | L26: 45173 | M26: =NETWORKDAYS(I26,J26) -> 9 | N26: =IF(K26="",0,NETWORKDAYS(I26,K26)) -> 9 | O26: =IF(L26="",0,NETWORKDAYS(I26,L26)) -> 17 | P26: Joined | R26: Sagar Kharche joined on 4th September
A27: =A26+1 -> 26 | B27: India | C27: Development | D27: PS | E27: Developer(FX) | F27: Replacement | H27: Pune | I27: 45149 | J27: 45161 | K27: 45161 | L27: 45173 | M27: =NETWORKDAYS(I27,J27) -> 9 | N27: =IF(K27="",0,NETWORKDAYS(I27,K27)) -> 9 | O27: =IF(L27="",0,NETWORKDAYS(I27,L27)) -> 17 | P27: Joined | R27: Srikrushna joining on 4th September | T27: Hemant replacement | U27: Hemant replacement
A28: =A27+1 -> 27 | B28: India | C28: Quality Assurance | D28: FX | E28: Manual QA | F28: New | H28: Chennai | I28: 45149 | J28: 45162 | K28: 45162 | L28: 45163 | M28: =NETWORKDAYS(I28,J28) -> 10 | N28: =IF(K28="",0,NETWORKDAYS(I28,K28)) -> 10 | O28: =IF(L28="",0,NETWORKDAYS(I28,L28)) -> 11 | P28: Joined | R28: Hari Sankar, DOJ: 25th August 2023
A29: =A28+1 -> 28 | B29: India | C29: Operations | D29: HR | E29: Recruitment | F29: New | H29: Chennai | I29: 45149 | J29: 45158 | K29: 45158 | L29: 45159 | M29: =NETWORKDAYS(I29,J29) -> 6 | N29: =IF(K29="",0,NETWORKDAYS(I29,K29)) -> 6 | O29: =IF(L29="",0,NETWORKDAYS(I29,L29)) -> 7 | P29: Joined | R29: Sugan Gopi joined on 21st Augut 2023
A30: =A29+1 -> 29 | B30: India | C30: Development | D30: FX | E30: Mid Developer | F30: New | H30: Chennai | I30: 45154 | J30: 45237 | K30: 45237 | L30: 45238 | M30: =NETWORKDAYS(I30,J30) -> 60 | N30: =IF(K30="",0,NETWORKDAYS(I30,K30)) -> 60 | O30: =IF(L30="",0,NETWORKDAYS(I30,L30)) -> 61 | P30: Joined | R30: Manikanda S joined
A31: =A30+1 -> 30 | B31: India | C31: BI | D31: Bank OS | E31: BI | F31: New | H31: Pune | I31: 45289 | J31: =TODAY() -> 46324 | M31: =NETWORKDAYS(I31,J31) -> 740 | N31: =IF(K31="",0,NETWORKDAYS(I31,K31)) -> 0 | O31: =IF(L31="",0,NETWORKDAYS(I31,L31)) -> 0 | P31: Suspended | R31: 2 Final Interview with Vijay/ L1 - 1 Sch. Suspended on 6-FEB-24 based on Atul's email. | S31: Sugan
A32: =A31+1 -> 31 | B32: India | C32: Quality Assurance | D32: PS | E32: QA | F32: Replacement | H32: Pune | I32: 45167 | J32: 45182 | K32: 45182 | L32: 45191 | M32: =NETWORKDAYS(I32,J32) -> 12 | N32: =IF(K32="",0,NETWORKDAYS(I32,K32)) -> 12 | O32: =IF(L32="",0,NETWORKDAYS(I32,L32)) -> 19 | P32: Joined | R32: Basalingaappa | T32: Tapan Replacement | U32: Tapan Replacement
A33: =A32+1 -> 32 | B33: India | C33: Development | D33: Bank OS | E33: Lead Engineer | F33: Backup | H33: Pune | I33: 45202 | J33: 45225 | K33: 45225 | L33: 45236 | M33: =NETWORKDAYS(I33,J33) -> 18 | N33: =IF(K33="",0,NETWORKDAYS(I33,K33)) -> 18 | O33: =IF(L33="",0,NETWORKDAYS(I33,L33)) -> 25 | P33: Joined | R33: Ganesh Kutaye joined on 6th November | T33: Uday Kumar | U33: Uday Kumar
A34: =A33+1 -> 33 | B34: India | C34: Quality Assurance | D34: Cash OS | E34: Automation Developer | F34: New | H34: Pune | I34: 45182 | J34: 45198 | K34: 45198 | L34: 45202 | M34: =NETWORKDAYS(I34,J34) -> 13 | N34: =IF(K34="",0,NETWORKDAYS(I34,K34)) -> 13 | O34: =IF(L34="",0,NETWORKDAYS(I34,L34)) -> 15 | P34: Joined | R34: Sarika
A35: =A34+1 -> 34 | B35: India | C35: Development | D35: Cash OS | E35: Mobile Developer (React Native) | F35: New | H35: Pune | I35: 45202 | J35: 45233 | K35: 45233 | L35: 45257 | M35: =NETWORKDAYS(I35,J35) -> 24 | N35: =IF(K35="",0,NETWORKDAYS(I35,K35)) -> 24 | O35: =IF(L35="",0,NETWORKDAYS(I35,L35)) -> 40 | P35: Joined | R35: Kishor Patil joined
A36: =A35+1 -> 35 | B36: India | C36: Development | D36: Cash OS | E36: Mid to Senior Level Full stack | F36: New | H36: Pune | I36: 45182 | J36: 45202 | K36: 45202 | L36: 45203 | M36: =NETWORKDAYS(I36,J36) -> 15 | N36: =IF(K36="",0,NETWORKDAYS(I36,K36)) -> 15 | O36: =IF(L36="",0,NETWORKDAYS(I36,L36)) -> 16 | P36: Joined | R36: Baskaran Joined
A37: =A36+1 -> 36 | B37: India | C37: Development | D37: Cash OS | E37: Mid-level Java developer | F37: New | H37: Pune | I37: 45182 | J37: 45198 | K37: 45198 | L37: 45209 | M37: =NETWORKDAYS(I37,J37) -> 13 | N37: =IF(K37="",0,NETWORKDAYS(I37,K37)) -> 13 | O37: =IF(L37="",0,NETWORKDAYS(I37,L37)) -> 20 | P37: Joined | R37: Akshay
A38: =A37+1 -> 37 | B38: USA | C38: Operations | D38: IT Admin | E38: System (IT) Administrator | F38: Replacement | H38: USA | I38: 45176 | J38: 45229 | K38: 45190 | L38: 45201 | M38: =NETWORKDAYS(I38,J38) -> 38 | N38: =IF(K38="",0,NETWORKDAYS(I38,K38)) -> 11 | O38: =IF(L38="",0,NETWORKDAYS(I38,L38)) -> 18 | P38: Joined | R38: Suman Vaishnav started on October 2, 2023 | T38: Ted replacement | U38: Ted replacement
A39: =A38+1 -> 38 | B39: USA | C39: Operations | D39: HR | E39: Recruiter | F39: New | H39: USA | I39: 45176 | J39: 45239 | K39: 45189 | L39: 45203 | M39: =NETWORKDAYS(I39,J39) -> 46 | N39: =IF(K39="",0,NETWORKDAYS(I39,K39)) -> 10 | O39: =IF(L39="",0,NETWORKDAYS(I39,L39)) -> 20 | P39: Joined | R39: Position was offered to Nella Rosas, she has accepted the offer.
A40: =A39+1 -> 39 | B40: USA | C40: Development | D40: Cash OS | E40: Senior API Developer | F40: New | H40: USA | I40: 45176 | J40: 45236 | K40: 45218 | L40: 45250 | M40: =NETWORKDAYS(I40,J40) -> 43 | N40: =IF(K40="",0,NETWORKDAYS(I40,K40)) -> 31 | O40: =IF(L40="",0,NETWORKDAYS(I40,L40)) -> 53 | P40: Joined | R40: Uday accepted the offer and started on December 4, 2023. | S40: Marissa
...

Sheet Master 2026
A1: Sr No | B1: Geo | C1: Department | D1: Squads | E1: Positions | F1: Dept Head | G1: New/Replacement | H1: Replaced Employee Name | I1: Full-Time/Consultant | J1: Hiring Location | K1: Position Open Date | L1: Todays Date | M1: Date Offered | N1: Joining Date | O1: Quarter Joining | P1: Aging (Days) | Q1: Position Offered | R1: Position Closed | S1: Status | T1: Offered Candidates | U1: Highest Qualification Degree | V1: Applied/ Sourced/ Reffered (Internal/External) | W1: RAG Status | X1: Back-up Plans | Y1: Buddy - Onboarding | Z1: Comments | AA1: Recruiter
A2: 1 | B2: India | C2: Product | D2: Account | E2: Product Manager | F2: Ashok | G2: Replacement | H2: Bhargav/Mahesh | I2: Full-time | J2: Chennai | K2: 45938 | L2: 45975 | M2: 45975 | N2: 46090 | P2: =NETWORKDAYS(K2,L2) -> 28 | Q2: =IF(M2="",0,NETWORKDAYS(K2,M2)) -> 28 | R2: =IF(N2="",0,NETWORKDAYS(K2,N2)) -> 109 | S2: Suspended | Z2: Narsimha Leela Krishna - Backedout | AA2: Thirukumaran
A3: 2 | B3: USA | C3: Infosec | D3: Infosec | E3: CISO (Change of Role) | F3: Murthy | G3: Replacement | H3: Nate | I3: Full-time | J3: Charlotte | K3: 45982 | L3: 46055 | M3: 46045 | N3: 46055 | O3: ="Q"&INT((MONTH(N3)-1)/3)+1 -> Q1 | P3: =NETWORKDAYS(K3,L3) -> 52 | Q3: =IF(M3="",0,NETWORKDAYS(K3,M3)) -> 46 | R3: =IF(N3="",0,NETWORKDAYS(K3,N3)) -> 52 | S3: Joined | T3: Supro | Z3: Eric Garcia decided to reject the offer on October 1, 2025. | AA3: Marissa
A4: 3 | B4: USA | C4: Product | D4: Payments | E4: Product Owner (Change of Role) | F4: Vijay | G4: New | I4: Full-time | J4: Charlotte | K4: 45895 | L4: 46042 | M4: 46003 | N4: 46042 | O4: ="Q"&INT((MONTH(N4)-1)/3)+1 -> Q1 | P4: =NETWORKDAYS(K4,L4) -> 106 | Q4: =IF(M4="",0,NETWORKDAYS(K4,M4)) -> 79 | R4: =IF(N4="",0,NETWORKDAYS(K4,N4)) -> 106 | S4: Joined | T4: Melissa | Z4: Melissa will join in January 12, 2025 | AA4: Marissa
A5: 4 | B5: USA | C5: Engineering | D5: Payments | E5: Enterprise Architect | F5: Murthy | G5: New | H5: N/A | I5: Full-time | J5: Charlotte | K5: 46024 | L5: 46132 | M5: 46105 | N5: 46132 | O5: ="Q"&INT((MONTH(N5)-1)/3)+1 -> Q2 | P5: =NETWORKDAYS(K5,L5) -> 77 | Q5: =IF(M5="",0,NETWORKDAYS(K5,M5)) -> 58 | R5: =IF(N5="",0,NETWORKDAYS(K5,N5)) -> 77 | S5: Joined | T5: Lakshminarayan | AA5: Andleeb
A6: 5 | B6: India | C6: Engineering | D6: Payments | E6: Senior Software Engineer | F6: Vinay | G6: Replacement | H6: Revanth | I6: Full-time | J6: Chennai | K6: 45958 | L6: 46003 | M6: 46003 | N6: 46042 | O6: ="Q"&INT((MONTH(N6)-1)/3)+1 -> Q1 | P6: =NETWORKDAYS(K6,L6) -> 34 | Q6: =IF(M6="",0,NETWORKDAYS(K6,M6)) -> 34 | R6: =IF(N6="",0,NETWORKDAYS(K6,N6)) -> 61 | S6: Joined | T6: Srinivasan | V6: Internal | AA6: Thirukumaran
A7: 6 | B7: India | C7: DevOps | D7: DevOps | E7: DevOps Engineer | F7: Prathap | G7: New | I7: Full-time | J7: Chennai | K7: 46024 | L7: 46085 | M7: 46085 | N7: 46086 | O7: ="Q"&INT((MONTH(N7)-1)/3)+1 -> Q1 | P7: =NETWORKDAYS(K7,L7) -> 44 | Q7: =IF(M7="",0,NETWORKDAYS(K7,M7)) -> 44 | R7: =IF(N7="",0,NETWORKDAYS(K7,N7)) -> 45 | S7: Joined | T7: Senthil R | V7: Internal | AA7: Andleeb
A8: 7 | B8: India | C8: DevOps | D8: DevOps | E8: Senior DevOps Engineer | F8: Prathap | G8: New | I8: Full-time | J8: Pune | K8: 46214 | L8: =TODAY() -> 46324 | P8: =NETWORKDAYS(K8,L8) -> 79 | Q8: =IF(M8="",0,NETWORKDAYS(K8,M8)) -> 0 | R8: =IF(N8="",0,NETWORKDAYS(K8,N8)) -> 0 | S8: Suspended | Z8: Role changed to IT Admin (email from Aarthie) | AA8: Andleeb/Thirukumaran
A9: 8 | B9: India | C9: QA | D9: Payments | E9: Performance Tester | F9: Divya | G9: Replacement | H9: Mageshkumar | I9: Full-time | J9: Chennai | K9: 46028 | L9: 46031 | M9: 46031 | N9: 46041 | O9: ="Q"&INT((MONTH(N9)-1)/3)+1 -> Q1 | P9: =NETWORKDAYS(K9,L9) -> 4 | Q9: =IF(M9="",0,NETWORKDAYS(K9,M9)) -> 4 | R9: =IF(N9="",0,NETWORKDAYS(K9,N9)) -> 10 | S9: Joined | T9: Pavithra Devi | V9: Internal | Z9: Pavithra Devi early attrition | AA9: Andleeb
A10: 9 | B10: India | C10: Engineering | D10: PS | E10: Senior Software Engineer | F10: Kanan | G10: Replacement | H10: Nikhilesh | I10: Consultant | J10: Pune | K10: 45945 | L10: 46094 | M10: 46094 | N10: 46104 | O10: ="Q"&INT((MONTH(N10)-1)/3)+1 -> Q1 | P10: =NETWORKDAYS(K10,L10) -> 108 | Q10: =IF(M10="",0,NETWORKDAYS(K10,M10)) -> 108 | R10: =IF(N10="",0,NETWORKDAYS(K10,N10)) -> 114 | S10: Joined | T10: Uttkarsh | V10: External | AA10: Vendor / Andleeb
A11: 10 | B11: USA | C11: DevOps | D11: DevOps | E11: Director of Infrastructure | F11: Murthy | G11: New | I11: Full-time | J11: Charlotte | K11: 45965 | L11: 46057 | M11: 46042 | N11: 46057 | O11: ="Q"&INT((MONTH(N11)-1)/3)+1 -> Q1 | P11: =NETWORKDAYS(K11,L11) -> 67 | Q11: =IF(M11="",0,NETWORKDAYS(K11,M11)) -> 56 | R11: =IF(N11="",0,NETWORKDAYS(K11,N11)) -> 67 | S11: Joined | T11: Manoj | AA11: Marissa
A12: 11 | B12: USA | C12: DevOps | D12: DevOps | E12: SecOps - Enterprise Governance | F12: Murthy | G12: New | I12: Full-time | J12: Charlotte | K12: 45966 | L12: =TODAY() -> 46324 | P12: =NETWORKDAYS(K12,L12) -> 257 | Q12: =IF(M12="",0,NETWORKDAYS(K12,M12)) -> 0 | R12: =IF(N12="",0,NETWORKDAYS(K12,N12)) -> 0 | S12: Suspended | Z12: Murthy asked to temp hold the req until the clarity on business need | AA12: Andleeb
A13: 12 | B13: USA | C13: Engineering | D13: Account | E13: Java Architect | F13: Ashok | G13: New | I13: Full-time | J13: Charlotte | K13: 45979 | L13: 46129 | M13: 46076 | N13: 46129 | O13: ="Q"&INT((MONTH(N13)-1)/3)+1 -> Q2 | P13: =NETWORKDAYS(K13,L13) -> 109 | Q13: =IF(M13="",0,NETWORKDAYS(K13,M13)) -> 70 | R13: =IF(N13="",0,NETWORKDAYS(K13,N13)) -> 109 | S13: Joined | T13: Esther M | AA13: Marissa
A14: 13 | B14: India | C14: Engineering | D14: Trade | E14: Software Engineer | F14: Raju | G14: Replacement | H14: Manikandan S | I14: Full-time | J14: Chennai | K14: 46024 | L14: 46057 | M14: 46057 | N14: 46146 | O14: ="Q"&INT((MONTH(N14)-1)/3)+1 -> Q2 | P14: =NETWORKDAYS(K14,L14) -> 24 | Q14: =IF(M14="",0,NETWORKDAYS(K14,M14)) -> 24 | R14: =IF(N14="",0,NETWORKDAYS(K14,N14)) -> 87 | S14: Joined | T14: Sridharan | V14: Internal | Z14: Sridharan - Backup / Manikandan Resigned | AA14: Thirukumaran
A15: 14 | B15: USA | C15: Finance | D15: Finance | E15: Chief Finance Officer | F15: Booshan | G15: Replacement | H15: Adam | I15: Full-time | J15: Charlotte | K15: 46009 | L15: =TODAY() -> 46324 | M15: 46283 | N15: 46314 | P15: =NETWORKDAYS(K15,L15) -> 226 | Q15: =IF(M15="",0,NETWORKDAYS(K15,M15)) -> 197 | R15: =IF(N15="",0,NETWORKDAYS(K15,N15)) -> 218 | S15: Joined | T15: Jack McCullen | AA15: TPZ
A16: 15 | B16: India | C16: Engineering | D16: Trade | E16: Software Engineer | F16: Raju | G16: Replacement | H16: Ambikeshwari | I16: Full-time | J16: Chennai | K16: 46015 | L16: 46107 | M16: 46107 | N16: 46108 | O16: ="Q"&INT((MONTH(N16)-1)/3)+1 -> Q1 | P16: =NETWORKDAYS(K16,L16) -> 67 | Q16: =IF(M16="",0,NETWORKDAYS(K16,M16)) -> 67 | R16: =IF(N16="",0,NETWORKDAYS(K16,N16)) -> 68 | S16: Joined | T16: Elumalai | V16: Internal | Z16: Ambikeshwari Resigned | AA16: Thirukumaran
A17: 16 | B17: USA | C17: Sales | D17: Sales | E17: VP of PreSales and Solution Consulting | F17: Karuna | G17: New | I17: Full-time | J17: USA-Remote | K17: 46003 | L17: 46062 | M17: 46014 | N17: 46062 | O17: ="Q"&INT((MONTH(N17)-1)/3)+1 -> Q1 | P17: =NETWORKDAYS(K17,L17) -> 42 | Q17: =IF(M17="",0,NETWORKDAYS(K17,M17)) -> 8 | R17: =IF(N17="",0,NETWORKDAYS(K17,N17)) -> 42 | S17: Joined | T17: Romil | AA17: Marissa
A18: 17 | B18: USA | C18: Sales | D18: Sales | E18: VP of Sales - Payments | F18: Karuna | G18: New | I18: Full-time | J18: USA-Remote | K18: 45981 | L18: 46031 | M18: 46015 | N18: 46031 | O18: ="Q"&INT((MONTH(N18)-1)/3)+1 -> Q1 | P18: =NETWORKDAYS(K18,L18) -> 37 | Q18: =IF(M18="",0,NETWORKDAYS(K18,M18)) -> 25 | R18: =IF(N18="",0,NETWORKDAYS(K18,N18)) -> 37 | S18: Joined | T18: Randy | AA18: Marissa
A19: 18 | B19: India | C19: HR | D19: HR | E19: HR Executive (HRBP) | F19: Bharath | G19: Replacement | H19: Baskaran D | I19: Full-time | J19: Chennai | K19: 46013 | L19: =TODAY() -> 46324 | M19: 46047 | N19: 46050 | O19: ="Q"&INT((MONTH(N19)-1)/3)+1 -> Q1 | P19: =NETWORKDAYS(K19,L19) -> 224 | Q19: =IF(M19="",0,NETWORKDAYS(K19,M19)) -> 25 | R19: =IF(N19="",0,NETWORKDAYS(K19,N19)) -> 28 | S19: Joined | T19: Janani | V19: Internal | AA19: Andleeb
A20: 19 | B20: India | C20: HR | D20: HR | E20: HR Ops | F20: Bharath | G20: Replacement | H20: Baskaran D | I20: Full-time | J20: Chennai | K20: 46013 | L20: =TODAY() -> 46324 | M20: 46041 | N20: 46042 | O20: ="Q"&INT((MONTH(N20)-1)/3)+1 -> Q1 | P20: =NETWORKDAYS(K20,L20) -> 224 | Q20: =IF(M20="",0,NETWORKDAYS(K20,M20)) -> 21 | R20: =IF(N20="",0,NETWORKDAYS(K20,N20)) -> 22 | S20: Joined | T20: Abirami R | V20: Internal | AA20: Andleeb
A21: 20 | B21: India | C21: QA | D21: PS | E21: Quality Analyst (C2H) | F21: Kanan | G21: Replacement | H21: Vineet K | I21: Consultant | J21: Pune | K21: 46024 | L21: =TODAY() -> 46324 | M21: 46038 | N21: 46055 | O21: ="Q"&INT((MONTH(N21)-1)/3)+1 -> Q1 | P21: =NETWORKDAYS(K21,L21) -> 215 | Q21: =IF(M21="",0,NETWORKDAYS(K21,M21)) -> 11 | R21: =IF(N21="",0,NETWORKDAYS(K21,N21)) -> 22 | S21: Joined | T21: Shubhankar | V21: External | Z21: DOJ Feb 4 - by Synechron | AA21: Vendor
A22: 21 | B22: India | C22: Engineering | D22: Payments | E22: Software Engineer (Rust) | F22: Prashant | G22: Replacement | H22: Ganesh | I22: Full-time | J22: Pune | K22: 46034 | L22: 46052 | M22: 46052 | N22: 46058 | O22: ="Q"&INT((MONTH(N22)-1)/3)+1 -> Q1 | P22: =NETWORKDAYS(K22,L22) -> 15 | Q22: =IF(M22="",0,NETWORKDAYS(K22,M22)) -> 15 | R22: =IF(N22="",0,NETWORKDAYS(K22,N22)) -> 19 | S22: Joined | T22: Anil P | V22: Internal | AA22: Andleeb
A23: 22 | B23: India | C23: Product | D23: Account | E23: Product Manager - VA | F23: Ashok | G23: New | I23: Full-time | J23: Pune | K23: 46024 | L23: 46049 | M23: 46049 | N23: 46140 | O23: ="Q"&INT((MONTH(N23)-1)/3)+1 -> Q2 | P23: =NETWORKDAYS(K23,L23) -> 18 | Q23: =IF(M23="",0,NETWORKDAYS(K23,M23)) -> 18 | R23: =IF(N23="",0,NETWORKDAYS(K23,N23)) -> 83 | S23: Joined | T23: Dhawal | V23: Internal | AA23: Thirukumaran
A24: 23 | B24: India | C24: QA | D24: Account | E24: QA Analyst | F24: Ashok | G24: New | I24: Full-time | J24: Chennai | K24: 46043 | L24: 46052 | M24: 46052 | N24: 46093 | O24: ="Q"&INT((MONTH(N24)-1)/3)+1 -> Q1 | P24: =NETWORKDAYS(K24,L24) -> 8 | Q24: =IF(M24="",0,NETWORKDAYS(K24,M24)) -> 8 | R24: =IF(N24="",0,NETWORKDAYS(K24,N24)) -> 37 | S24: Joined | T24: Nikhil C Karanam | V24: Internal | Z24: Nikhil early attrition | AA24: Thirukumaran
A25: 24 | B25: India | C25: QA | D25: Account | E25: QA Analyst | F25: Ashok | G25: New | I25: Full-time | J25: Chennai | K25: 46043 | L25: 46057 | M25: 46057 | N25: 46083 | O25: ="Q"&INT((MONTH(N25)-1)/3)+1 -> Q1 | P25: =NETWORKDAYS(K25,L25) -> 11 | Q25: =IF(M25="",0,NETWORKDAYS(K25,M25)) -> 11 | R25: =IF(N25="",0,NETWORKDAYS(K25,N25)) -> 29 | S25: Joined | T25: Keerthika | V25: Internal | AA25: Thirukumaran
A26: 25 | B26: India | C26: Product | D26: Payments | E26: Payment Owner | F26: Kasi | G26: Replacement | H26: Ravikumar Kasi | I26: Full-time | J26: Chennai | K26: 46043 | L26: 46052 | M26: 46052 | N26: 46077 | O26: ="Q"&INT((MONTH(N26)-1)/3)+1 -> Q1 | P26: =NETWORKDAYS(K26,L26) -> 8 | Q26: =IF(M26="",0,NETWORKDAYS(K26,M26)) -> 8 | R26: =IF(N26="",0,NETWORKDAYS(K26,N26)) -> 25 | S26: Joined | T26: Ganesh | V26: Internal | Z26: Sujata on hold | AA26: Andleeb
A27: 26 | B27: India | C27: Prod Support | D27: Support | E27: Production Support Engineer (FX) | F27: Mark D | G27: New | I27: Full-time | J27: India-Remote | K27: 46043 | L27: =TODAY() -> 46324 | M27: 46052 | N27: 46058 | O27: ="Q"&INT((MONTH(N27)-1)/3)+1 -> Q1 | P27: =NETWORKDAYS(K27,L27) -> 202 | Q27: =IF(M27="",0,NETWORKDAYS(K27,M27)) -> 8 | R27: =IF(N27="",0,NETWORKDAYS(K27,N27)) -> 12 | S27: Joined | T27: Krishnaprasad | V27: Emp Ref | AA27: Andleeb
A28: 27 | B28: India | C28: BA | D28: PS | E28: Business Analyst | F28: Kanan | G28: New | I28: Full-time | J28: Pune | K28: 46049 | L28: 46057 | M28: 46057 | N28: 46122 | O28: ="Q"&INT((MONTH(N28)-1)/3)+1 -> Q2 | P28: =NETWORKDAYS(K28,L28) -> 7 | Q28: =IF(M28="",0,NETWORKDAYS(K28,M28)) -> 7 | R28: =IF(N28="",0,NETWORKDAYS(K28,N28)) -> 54 | S28: Joined | T28: Niraj T | V28: Emp Ref | AA28: Andleeb
A29: 28 | B29: India | C29: Legal | D29: Support | E29: India Legal Assistant supporting US | F29: Hardik | G29: New | I29: Full-time | J29: India-Remote | K29: 46049 | L29: =TODAY() -> 46324 | M29: 46064 | N29: 46070 | O29: ="Q"&INT((MONTH(N29)-1)/3)+1 -> Q1 | P29: =NETWORKDAYS(K29,L29) -> 198 | Q29: =IF(M29="",0,NETWORKDAYS(K29,M29)) -> 12 | R29: =IF(N29="",0,NETWORKDAYS(K29,N29)) -> 16 | S29: Joined | T29: Uzma Sohail | V29: Emp Ref | AA29: Thirukumaran
A30: 29 | B30: India | C30: Product | D30: Digital | E30: Product Manager- DGx & OpenAPI | F30: Sajeesh | G30: New | I30: Full-time | J30: Pune | K30: 46064 | L30: =TODAY() -> 46324 | N30: 46091 | O30: ="Q"&INT((MONTH(N30)-1)/3)+1 -> Q1 | P30: =NETWORKDAYS(K30,L30) -> 187 | Q30: =IF(M30="",0,NETWORKDAYS(K30,M30)) -> 0 | R30: =IF(N30="",0,NETWORKDAYS(K30,N30)) -> 20 | S30: Joined | T30: Alice Marks | V30: Internal | AA30: Thirukumaran
A31: 30 | B31: India | C31: Engineering | D31: Digital | E31: Full-stack Engineer | F31: Sajeesh | G31: New | I31: Full-time | J31: Pune | K31: 46064 | L31: 46085 | M31: 46085 | N31: 46107 | O31: ="Q"&INT((MONTH(N31)-1)/3)+1 -> Q1 | P31: =NETWORKDAYS(K31,L31) -> 16 | Q31: =IF(M31="",0,NETWORKDAYS(K31,M31)) -> 16 | R31: =IF(N31="",0,NETWORKDAYS(K31,N31)) -> 32 | S31: Joined | T31: Omkar Chavan | V31: Internal | AA31: Thirukumaran
A32: 31 | B32: India | C32: BA | D32: Trade | E32: BA- FX | F32: Patrick | G32: New | I32: Full-time | J32: Chennai | K32: 46144 | L32: 46175 | M32: 46174 | N32: 46175 | O32: ="Q"&INT((MONTH(N32)-1)/3)+1 -> Q2 | P32: =NETWORKDAYS(K32,L32) -> 22 | Q32: =IF(M32="",0,NETWORKDAYS(K32,M32)) -> 21 | R32: =IF(N32="",0,NETWORKDAYS(K32,N32)) -> 22 | S32: Joined | T32: Muthu Meenakshi | V32: External | AA32: Thirukumaran
A33: 32 | B33: India | C33: BA | D33: Trade | E33: Business Analyst - IRD | F33: Patrick | G33: New | I33: Full-time | J33: Chennai | K33: 46144 | L33: 46190 | M33: 46190 | N33: 46283 | O33: ="Q"&INT((MONTH(N33)-1)/3)+1 -> Q3 | P33: =NETWORKDAYS(K33,L33) -> 33 | Q33: =IF(M33="",0,NETWORKDAYS(K33,M33)) -> 33 | R33: =IF(N33="",0,NETWORKDAYS(K33,N33)) -> 100 | S33: Joined | T33: Kishore | V33: Internal | W33: Amber | X33: Initial Interview | Y33: Karthikeyan | Z33: Kishore accpeted our offer | AA33: Thirukumaran
A34: 33 | B34: India | C34: Engineering | D34: Account | E34: Full-stack Engineer | F34: Ashok | G34: New | I34: Full-time | J34: Chennai | K34: 46064 | L34: 46141 | M34: 46141 | N34: 46162 | O34: ="Q"&INT((MONTH(N34)-1)/3)+1 -> Q2 | P34: =NETWORKDAYS(K34,L34) -> 56 | Q34: =IF(M34="",0,NETWORKDAYS(K34,M34)) -> 56 | R34: =IF(N34="",0,NETWORKDAYS(K34,N34)) -> 71 | S34: Joined | T34: Kalirajan | V34: Emp Ref | Z34: Sivakumar Backedout | AA34: Thirukumaran
A35: 34 | B35: India | C35: Program | D35: Payments | E35: Project Manager | F35: Ramesh | G35: New | I35: Full-time | J35: Pune | K35: 46055 | L35: 46210 | M35: 46210 | N35: 46232 | O35: ="Q"&INT((MONTH(N35)-1)/3)+1 -> Q3 | P35: =NETWORKDAYS(K35,L35) -> 112 | Q35: =IF(M35="",0,NETWORKDAYS(K35,M35)) -> 112 | R35: =IF(N35="",0,NETWORKDAYS(K35,N35)) -> 128 | S35: Joined | T35: Naveen Kulkarni | V35: Emp Ref | W35: Green | X35: Initial Interview | Y35: Amit Kulkarni | Z35: Naveen accepted our offered | AA35: Andleeb
A36: 35 | B36: India | C36: DevOps | D36: DevOps | E36: DevOps Engineer | F36: Prathap | G36: New | I36: Full-time | J36: Pune | K36: 46144 | L36: 46184 | M36: 46184 | N36: 46188 | O36: ="Q"&INT((MONTH(N36)-1)/3)+1 -> Q2 | P36: =NETWORKDAYS(K36,L36) -> 29 | Q36: =IF(M36="",0,NETWORKDAYS(K36,M36)) -> 29 | R36: =IF(N36="",0,NETWORKDAYS(K36,N36)) -> 31 | S36: Joined | T36: Faheem | V36: Internal | AA36: Andleeb
A37: 36 | B37: India | C37: DevOps | D37: DevOps | E37: DevOps Engineer | F37: Prathap | G37: New | I37: Full-time | J37: Chennai | K37: 46144 | L37: 46178 | M37: 46178 | N37: 46181 | O37: ="Q"&INT((MONTH(N37)-1)/3)+1 -> Q2 | P37: =NETWORKDAYS(K37,L37) -> 25 | Q37: =IF(M37="",0,NETWORKDAYS(K37,M37)) -> 25 | R37: =IF(N37="",0,NETWORKDAYS(K37,N37)) -> 26 | S37: Joined | T37: Deepakraj J | V37: Internal | AA37: Thirukumaran
A38: 37 | B38: India | C38: Infosec | D38: Infosec | E38: InfoSec Security Analyst | F38: Supro | G38: New | I38: Full-time | J38: Pune | K38: 46110 | L38: 46206 | M38: 46206 | N38: 46211 | O38: ="Q"&INT((MONTH(N38)-1)/3)+1 -> Q3 | P38: =NETWORKDAYS(K38,L38) -> 70 | Q38: =IF(M38="",0,NETWORKDAYS(K38,M38)) -> 70 | R38: =IF(N38="",0,NETWORKDAYS(K38,N38)) -> 73 | S38: Joined | T38: Rajesh | V38: Internal | W38: Green | X38: Sourcing | Z38: Swapnil/Gauresh / Nitesh declined our offer. Supro referral is looking remote | AA38: Andleeb
A39: 38 | B39: India | C39: Infosec | D39: Infosec | E39: InfoSec Audit & Compliance Engineer | F39: Supro | G39: New | I39: Full-time | J39: Pune | K39: 46064 | L39: 46105 | M39: 46105 | N39: 46106 | O39: ="Q"&INT((MONTH(N39)-1)/3)+1 -> Q1 | P39: =NETWORKDAYS(K39,L39) -> 30 | Q39: =IF(M39="",0,NETWORKDAYS(K39,M39)) -> 30 | R39: =IF(N39="",0,NETWORKDAYS(K39,N39)) -> 31 | S39: Joined | T39: Sayyed Karim | V39: Internal | AA39: Andleeb
A40: 39 | B40: India | C40: Program | D40: Payments | E40: Scrum Master | F40: Vijay | G40: Replacement | H40: Saravanan T | I40: Full-time | J40: Pune | K40: 46063 | L40: =TODAY() -> 46324 | N40: 46086 | O40: ="Q"&INT((MONTH(N40)-1)/3)+1 -> Q1 | P40: =NETWORKDAYS(K40,L40) -> 188 | Q40: =IF(M40="",0,NETWORKDAYS(K40,M40)) -> 0 | R40: =IF(N40="",0,NETWORKDAYS(K40,N40)) -> 18 | S40: Joined | T40: Amit KS | V40: Internal | AA40: Andleeb
...

Sheet Challenges
B1: INDIA
A5: Practice | B5: Positions | C5: Hiring Manager | D5: Challenges | E5: HR Solutions
A6: Infosec | B6: Infosec Analyst | C6: Supro | D6: • 3 candidates (Swapnil/Nitesh/Gauresh) declined our offer. • Limited pool of candidates with short notice. | E6: •Open the role to consulting firm. • Schedule the interview with shorter notice period.
A7: Payments | B7: Project Manager | C7: Ramesh | D7: • 2 candidates (Bhavik/Harsh) declined our offer • High Notice period candidates •Candidates preferred only working in office. | E7: • Shared the role with the consulting firms. Ex- employee (Naveen) scheduled with Ramesh this week Friday.
B12: USA
A13: Practice | B13: Positions | C13: Hiring Manager | D13: Challenges | E13: HR Solutions
A14: Finance | B14: CFO | C14: Booshan | D14: The CFO search yielded limited qualified candidates, with the talent pool failing to meet the strategic and technical requirements of the role. | E14: Partner with a specialized executive search firm to broaden the CFO candidate pipeline and access passive, high-caliber talent beyond standard recruitment channels.
A15: DevOps | B15: DevOps Engineer | C15: Manoj S. | D15: Current applicants are either demonstrating indications of interview integrity concerns or are failing to meet required technical competencies for the role. | E15: We plan to expand visibility on LinkedIn as an immediate next step and will evaluate engaging a third‑party recruiting firm if the hiring timeline extends.

Sheet Data Validation
A1: JD Pending | B1: Pune | C1: Full-time | D1: India | E1: New
A2: Screening | B2: Chennai | C2: Consultant | D2: USA | E2: Replacement
A3: Sourcing | B3: India-Remote | C3: Full-time/Consultant
A4: Initial Interview | B4: Charlotte | C4: Contractor
A5: Final Interview | B5: USA-Remote
A6: HR Interview | B6: Chennai/Pune
A7: Offer Approval
A8: Offered
A9: Joined
A10: Temp Hold
A11: Approval Pending
A12: AI Interview
A13: L1 Process
A14: Case study
A15: Profile shared
A16: Position Freezed
A17: Unapproved Postion
A18: Internal Movement
A19: Suspended

Sheet Livefeed
A1: Sr No | B1: Geo | C1: Department | D1: Squads | E1: Positions | F1: Dept Head | G1: New/Replacement | H1: Replaced Employee Name | I1: Full-Time/Consultant | J1: Hiring Location | K1: Position Open Date | L1: Todays Date | M1: Date Offered | N1: Joining Date | O1: Quarter Joining | P1: Aging (Days) | Q1: Position Offered | R1: Position Closed | S1: Status | T1: Offered Candidates | U1: Highest Qualification Degree | V1: Applied/ Sourced/ Reffered (Internal/External) | W1: RAG Status | X1: Back-up Plans | Y1: Buddy - Onboarding | Z1: Comments | AA1: Recruiter
A2: ='Master 2026'!A2 -> 1 | B2: ='Master 2026'!B2 -> India | C2: ='Master 2026'!C2 -> Product | D2: ='Master 2026'!D2 -> Account | E2: ='Master 2026'!E2 -> Product Manager | F2: ='Master 2026'!F2 -> Ashok | G2: ='Master 2026'!G2 -> Replacement | H2: ='Master 2026'!H2 -> Bhargav/Mahesh | ... AA2: ='Master 2026'!AA2 -> Thirukumaran
A3: ='Master 2026'!A3 -> 2 | B3: ='Master 2026'!B3 -> USA | C3: ='Master 2026'!C3 -> Infosec | D3: ='Master 2026'!D3 -> Infosec | E3: ='Master 2026'!E3 -> CISO (Change of Role) | F3: ='Master 2026'!F3 -> Murthy | G3: ='Master 2026'!G3 -> Replacement | H3: ='Master 2026'!H3 -> Nate | ... AA3: ='Master 2026'!AA3 -> Marissa
A4: ='Master 2026'!A4 -> 3 | B4: ='Master 2026'!B4 -> USA | C4: ='Master 2026'!C4 -> Product | D4: ='Master 2026'!D4 -> Payments | E4: ='Master 2026'!E4 -> Product Owner (Change of Role) | F4: ='Master 2026'!F4 -> Vijay | G4: ='Master 2026'!G4 -> New | H4: ='Master 2026'!H4 -> 0 | ... AA4: ='Master 2026'!AA4 -> Marissa
A5: ='Master 2026'!A5 -> 4 | B5: ='Master 2026'!B5 -> USA | C5: ='Master 2026'!C5 -> Engineering | D5: ='Master 2026'!D5 -> Payments | E5: ='Master 2026'!E5 -> Enterprise Architect | F5: ='Master 2026'!F5 -> Murthy | G5: ='Master 2026'!G5 -> New | H5: ='Master 2026'!H5 -> N/A | ... AA5: ='Master 2026'!AA5 -> Andleeb
A6: ='Master 2026'!A6 -> 5 | B6: ='Master 2026'!B6 -> India | C6: ='Master 2026'!C6 -> Engineering | D6: ='Master 2026'!D6 -> Payments | E6: ='Master 2026'!E6 -> Senior Software Engineer | F6: ='Master 2026'!F6 -> Vinay | G6: ='Master 2026'!G6 -> Replacement | H6: ='Master 2026'!H6 -> Revanth | ... AA6: ='Master 2026'!AA6 -> Thirukumaran
A7: ='Master 2026'!A7 -> 6 | B7: ='Master 2026'!B7 -> India | C7: ='Master 2026'!C7 -> DevOps | D7: ='Master 2026'!D7 -> DevOps | E7: ='Master 2026'!E7 -> DevOps Engineer | F7: ='Master 2026'!F7 -> Prathap | G7: ='Master 2026'!G7 -> New | H7: ='Master 2026'!H7 -> 0 | ... AA7: ='Master 2026'!AA7 -> Andleeb
A8: ='Master 2026'!A8 -> 7 | B8: ='Master 2026'!B8 -> India | C8: ='Master 2026'!C8 -> DevOps | D8: ='Master 2026'!D8 -> DevOps | E8: ='Master 2026'!E8 -> Senior DevOps Engineer | F8: ='Master 2026'!F8 -> Prathap | G8: ='Master 2026'!G8 -> New | H8: ='Master 2026'!H8 -> 0 | ... AA8: ='Master 2026'!AA8 -> Andleeb/Thirukumaran
A9: ='Master 2026'!A9 -> 8 | B9: ='Master 2026'!B9 -> India | C9: ='Master 2026'!C9 -> QA | D9: ='Master 2026'!D9 -> Payments | E9: ='Master 2026'!E9 -> Performance Tester | F9: ='Master 2026'!F9 -> Divya | G9: ='Master 2026'!G9 -> Replacement | H9: ='Master 2026'!H9 -> Mageshkumar | ... AA9: ='Master 2026'!AA9 -> Andleeb
A10: ='Master 2026'!A10 -> 9 | B10: ='Master 2026'!B10 -> India | C10: ='Master 2026'!C10 -> Engineering | D10: ='Master 2026'!D10 -> PS | E10: ='Master 2026'!E10 -> Senior Software Engineer | F10: ='Master 2026'!F10 -> Kanan | G10: ='Master 2026'!G10 -> Replacement | H10: ='Master 2026'!H10 -> Nikhilesh | ... AA10: ='Master 2026'!AA10 -> Vendor / Andleeb
A11: ='Master 2026'!A11 -> 10 | B11: ='Master 2026'!B11 -> USA | C11: ='Master 2026'!C11 -> DevOps | D11: ='Master 2026'!D11 -> DevOps | E11: ='Master 2026'!E11 -> Director of Infrastructure | F11: ='Master 2026'!F11 -> Murthy | G11: ='Master 2026'!G11 -> New | H11: ='Master 2026'!H11 -> 0 | ... AA11: ='Master 2026'!AA11 -> Marissa
A12: ='Master 2026'!A12 -> 11 | B12: ='Master 2026'!B12 -> USA | C12: ='Master 2026'!C12 -> DevOps | D12: ='Master 2026'!D12 -> DevOps | E12: ='Master 2026'!E12 -> SecOps - Enterprise Governance | F12: ='Master 2026'!F12 -> Murthy | G12: ='Master 2026'!G12 -> New | H12: ='Master 2026'!H12 -> 0 | ... AA12: ='Master 2026'!AA12 -> Andleeb
A13: ='Master 2026'!A13 -> 12 | B13: ='Master 2026'!B13 -> USA | C13: ='Master 2026'!C13 -> Engineering | D13: ='Master 2026'!D13 -> Account | E13: ='Master 2026'!E13 -> Java Architect | F13: ='Master 2026'!F13 -> Ashok | G13: ='Master 2026'!G13 -> New | H13: ='Master 2026'!H13 -> 0 | ... AA13: ='Master 2026'!AA13 -> Marissa
... A110: ='Master 2026'!A110 -> 109 | B110: ='Master 2026'!B110 -> India | C110: ='Master 2026'!C110 -> Delivery | D110: ='Master 2026'!D110 -> PS | E110: ='Master 2026'!E110 -> Director | F110: ='Master 2026'!F110 -> Kanan | G110: ='Master 2026'!G110 -> New | H110: ='Master 2026'!H110 -> 0 | ... AA110: ='Master 2026'!AA110 -> 0
A111: ='Master 2026'!A111 -> 110 | B111: ='Master 2026'!B111 -> India | C111: ='Master 2026'!C111 -> BA | D111: ='Master 2026'!D111 -> Payments | E111: ='Master 2026'!E111 -> Sr.Business Analyst | F111: ='Master 2026'!F111 -> Vijay | G111: ='Master 2026'!G111 -> Replacement | H111: ='Master 2026'!H111 -> Karthika C | ... N111: ='Master 2026'!N111 -> 46309 | O111: ='Master 2026'!O135 -> Q4 | P111: ='Master 2026'!P111 -> 19 | Q111: ='Master 2026'!Q111 -> 19 | R111: ='Master 2026'!R111 -> 81 | S111: ='Master 2026'!S111 -> Joined | T111: ='Master 2026'!T111 -> Gayathri | U111: ='Master 2026'!U111 -> 0 | V111: ='Master 2026'!V111 -> Emp Ref | W111: ='Master 2026'!W111 -> Green | ... AA111: ='Master 2026'!AA111 -> Andleeb
A112: ='Master 2026'!A112 -> 111 | B112: ='Master 2026'!B112 -> USA | C112: ='Master 2026'!C112 -> PS | D112: ='Master 2026'!D112 -> Account | E112: ='Master 2026'!E112 -> Solution Engineer | F112: ='Master 2026'!F112 -> Ashok | G112: ='Master 2026'!G112 -> New | H112: ='Master 2026'!H112 -> 0 | ... AA112: ='Master 2026'!AA112 -> Sindhu
A113: ='Master 2026'!A113 -> 112 | B113: ='Master 2026'!B113 -> USA | C113: ='Master 2026'!C113 -> Support | D113: ='Master 2026'!D113 -> Support | E113: ='Master 2026'!E113 -> Associate – Payment Production Support (Trainee) | F113: ='Master 2026'!F113 -> Anish | G113: ='Master 2026'!G113 -> New | H113: ='Master 2026'!H113 -> 0 | ... AA113: ='Master 2026'!AA113 -> Sindhu
A114: ='Master 2026'!A114 -> 113 | B114: ='Master 2026'!B114 -> India | C114: ='Master 2026'!C114 -> Support | D114: ='Master 2026'!D114 -> Support | E114: ='Master 2026'!E114 -> Production Support Engineer | F114: ='Master 2026'!F114 -> Mark/Anish | G114: ='Master 2026'!G114 -> Replacement | H114: ='Master 2026'!H114 -> Muzammil | ... AA114: ='Master 2026'!AA114 -> Thirukumaran
A115: ='Master 2026'!A115 -> 114 | B115: ='Master 2026'!B115 -> USA | C115: ='Master 2026'!C115 -> Support | D115: ='Master 2026'!D115 -> Support | E115: ='Master 2026'!E115 -> Associate - Payment Production Support(Trainee) | F115: ='Master 2026'!F115 -> Ranjith | G115: ='Master 2026'!G115 -> New | H115: ='Master 2026'!H115 -> 0 | ... AA115: ='Master 2026'!AA115 -> Sindhu
A116: ='Master 2026'!A116 -> 115 | B116: ='Master 2026'!B116 -> USA | C116: ='Master 2026'!C116 -> PS | D116: ='Master 2026'!D116 -> PS | E116: ='Master 2026'!E116 -> Associate - Implementation Analyst 1 | F116: ='Master 2026'!F116 -> Kanan | G116: ='Master 2026'!G116 -> New | H116: ='Master 2026'!H116 -> 0 | ... AA116: ='Master 2026'!AA116 -> Sindhu
A117: ='Master 2026'!A117 -> 116 | B117: ='Master 2026'!B117 -> USA | C117: ='Master 2026'!C117 -> PS | D117: ='Master 2026'!D117 -> PS | E117: ='Master 2026'!E117 -> Associate - Implementation Analyst 2 | F117: ='Master 2026'!F117 -> Kanan | G117: ='Master 2026'!G117 -> New | H117: ='Master 2026'!H117 -> 0 | ... AA117: ='Master 2026'!AA117 -> Sindhu
A118: ='Master 2026'!A118 -> 117 | B118: ='Master 2026'!B118 -> USA | C118: ='Master 2026'!C118 -> PS | D118: ='Master 2026'!D118 -> PS | E118: ='Master 2026'!E118 -> FX Business Analyst | F118: ='Master 2026'!F118 -> Kanan | G118: ='Master 2026'!G118 -> Replacement | H118: ='Master 2026'!H118 -> James | ... AA118: ='Master 2026'!AA118 -> Sindhu
A119: ='Master 2026'!A119 -> 118 | B119: ='Master 2026'!B119 -> India | C119: ='Master 2026'!C119 -> Engineering | D119: ='Master 2026'!D119 -> Payments | E119: ='Master 2026'!E119 -> Senior Software Engineer | F119: ='Master 2026'!F119 -> Vijay | G119: ='Master 2026'!G119 -> Replacement | H119: ='Master 2026'!H119 -> Maniprathap | ... AA119: ='Master 2026'!AA119 -> Andleeb
A120: ='Master 2026'!A120 -> 119 | B120: ='Master 2026'!B120 -> India | C120: ='Master 2026'!C120 -> Engineering | D120: ='Master 2026'!D120 -> Payments | E120: ='Master 2026'!E120 -> Application Architect | F120: ='Master 2026'!F120 -> Vijay | G120: ='Master 2026'!G120 -> Replacement | H120: ='Master 2026'!H120 -> Shankar | ... AA120: ='Master 2026'!AA120 -> 0
A121: ='Master 2026'!A121 -> 120 | B121: ='Master 2026'!B121 -> India | C121: ='Master 2026'!C121 -> Engineering | D121: ='Master 2026'!D121 -> Payments | E121: ='Master 2026'!E121 -> Senior Software Engineer | F121: ='Master 2026'!F121 -> Vijay | G121: ='Master 2026'!G121 -> Replacement | H121: ='Master 2026'!H121 -> Ganesh k | ... AA121: ='Master 2026'!AA121 -> Thirukumaran
A122: ='Master 2026'!A122 -> 121 | B122: ='Master 2026'!B122 -> India | C122: ='Master 2026'!C122 -> Engineering | D122: ='Master 2026'!D122 -> Payments | E122: ='Master 2026'!E122 -> Associate Software Engineer | F122: ='Master 2026'!F122 -> Vijay | G122: ='Master 2026'!G122 -> Replacement | H122: ='Master 2026'!H122 -> Shubham J | ... AA122: ='Master 2026'!AA122 -> Thirukumaran
A123: ='Master 2026'!A123 -> 122 | B123: ='Master 2026'!B123 -> USA | C123: ='Master 2026'!C123 -> PS | D123: ='Master 2026'!D123 -> Account | E123: ='Master 2026'!E123 -> Business Analyst | F123: ='Master 2026'!F123 -> Ashok | G123: ='Master 2026'!G123 -> New | H123: ='Master 2026'!H123 -> 0 | ... AA123: ='Master 2026'!AA123 -> Sindhu
... A134: ='Master 2026'!A134 -> 133 | B134: ='Master 2026'!B134 -> India | C134: ='Master 2026'!C134 -> Engineering | D134: ='Master 2026'!D134 -> Digital | E134: ='Master 2026'!E134 -> Associate Software Engineer | F134: ='Master 2026'!F134 -> Sajeesh | G134: ='Master 2026'!G134 -> Replacement | H134: ='Master 2026'!H134 -> Sai Shree | ... AA134: ='Master 2026'!AA134 -> 0
A135: ='Master 2026'!A135 -> 134 | B135: ='Master 2026'!B135 -> India | C135: ='Master 2026'!C135 -> Technology | D135: ='Master 2026'!D135 -> Technology | E135: ='Master 2026'!E135 -> Junior IT Admin | F135: ='Master 2026'!F135 -> Supro | G135: ='Master 2026'!G135 -> New | H135: ='Master 2026'!H135 -> 0 | ... N135: ='Master 2026'!N135 -> 46329 | O135: ='Master 2026'!#REF! -> #REF! | P135: ='Master 2026'!P135 -> 46 | Q135: ='Master 2026'!Q135 -> 46 | R135: ='Master 2026'!R135 -> 57 | S135: ='Master 2026'!S135 -> Offered | T135: ='Master 2026'!T135 -> Athiban Eswar | U135: ='Master 2026'!U135 -> 0 | V135: ='Master 2026'!V135 -> Internal | W135: ='Master 2026'!W135 -> Green | ... AA135: ='Master 2026'!AA135 -> Thirukumaran
A136: ='Master 2026'!A136 -> 135 | B136: ='Master 2026'!B136 -> India | C136: ='Master 2026'!C136 -> QA | D136: ='Master 2026'!D136 -> Payments | E136: ='Master 2026'!E136 -> Associate QA | F136: ='Master 2026'!F136 -> Vijay | G136: ='Master 2026'!G136 -> Replacement | H136: ='Master 2026'!H136 -> Gaurav D | ... AA136: ='Master 2026'!AA136 -> 0
A137: ='Master 2026'!A137 -> 136 | B137: ='Master 2026'!B137 -> India | C137: ='Master 2026'!C137 -> Support | D137: ='Master 2026'!D137 -> Support | E137: ='Master 2026'!E137 -> Production Support Engineer ( Payments) | F137: ='Master 2026'!F137 -> Anish | G137: ='Master 2026'!G137 -> Replacement | H137: ='Master 2026'!H137 -> Prince | ... AA137: ='Master 2026'!AA137 -> Andleeb
A138: ='Master 2026'!A138 -> 137 | B138: ='Master 2026'!B138 -> India | C138: ='Master 2026'!C138 -> HR | D138: ='Master 2026'!D138 -> HR | E138: ='Master 2026'!E138 -> Senior HR Manager | F138: ='Master 2026'!F138 -> Aarthie | G138: ='Master 2026'!G138 -> Replacement | H138: ='Master 2026'!H138 -> Bharathkumar M | ... AA138: ='Master 2026'!AA138 -> External
A139: ='Master 2026'!A139 -> 138 | B139: ='Master 2026'!B139 -> India | C139: ='Master 2026'!C139 -> Marketing | D139: ='Master 2026'!D139 -> GTM | E139: ='Master 2026'!E139 -> Director Marketing | F139: ='Master 2026'!F139 -> Suja | G139: ='Master 2026'!G139 -> New | H139: ='Master 2026'!H139 -> 0 | ... Y139: ='Master 2026'!Y139 -> 0 | Z139: ='Master 2026'!Z140 -> Karthik Joined us on 21st Sept | AA139: ='Master 2026'!AA139 -> External
A140: ='Master 2026'!A140 -> 139 | B140: ='Master 2026'!B140 -> India | C140: ='Master 2026'!C140 -> Marketing | D140: ='Master 2026'!D140 -> GTM | E140: ='Master 2026'!E140 -> Marketing Manager | F140: ='Master 2026'!F140 -> Suja | G140: ='Master 2026'!G140 -> New | H140: ='Master 2026'!H140 -> 0 | ... Y140: ='Master 2026'!Y140 -> 0 | Z140: ='Master 2026'!#REF! -> #REF! | AA140: ='Master 2026'!AA140 -> External
A141: ='Master 2026'!A141 -> 140 | B141: ='Master 2026'!B141 -> India | C141: ='Master 2026'!C141 -> Engineering | D141: ='Master 2026'!D141 -> Payments | E141: ='Master 2026'!E141 -> Associate Software Engineer | F141: ='Master 2026'!F141 -> Vijay | G141: ='Master 2026'!G141 -> Replacement | H141: ='Master 2026'!H141 -> Pradyumna | ... AA141: ='Master 2026'!AA141 -> 0
A142: ='Master 2026'!A142 -> 141 | B142: ='Master 2026'!B142 -> India | C142: ='Master 2026'!C142 -> Engineering | D142: ='Master 2026'!D142 -> Payments | E142: ='Master 2026'!E142 -> Associate Software Engineer | F142: ='Master 2026'!F142 -> Vijay | G142: ='Master 2026'!G142 -> Replacement | H142: ='Master 2026'!H142 -> Yogesh Y | ... AA142: ='Master 2026'!AA142 -> 0
A143: ='Master 2026'!A143 -> 142 | B143: ='Master 2026'!B143 -> India | C143: ='Master 2026'!C143 -> Engineering | D143: ='Master 2026'!D143 -> Payments | E143: ='Master 2026'!E143 -> Associate Software Engineer | F143: ='Master 2026'!F143 -> Vijay | G143: ='Master 2026'!G143 -> Replacement | H143: ='Master 2026'!H143 -> Vikrant J | ... AA143: ='Master 2026'!AA143 -> 0
A144: ='Master 2026'!A144 -> 143 | B144: ='Master 2026'!B144 -> India | C144: ='Master 2026'!C144 -> Engineering | D144: ='Master 2026'!D144 -> Payments | E144: ='Master 2026'!E144 -> Software Engineer | F144: ='Master 2026'!F144 -> Vijay | G144: ='Master 2026'!G144 -> Replacement | H144: ='Master 2026'!H144 -> Bhavik P | ... AA144: ='Master 2026'!AA144 -> 0
A145: ='Master 2026'!A145 -> 144 | B145: ='Master 2026'!B145 -> India | C145: ='Master 2026'!C145 -> DevOps | D145: ='Master 2026'!D145 -> DevOps | E145: ='Master 2026'!E145 -> Senior DevOps Engineer | F145: ='Master 2026'!F145 -> Manoj | G145: ='Master 2026'!G145 -> Replacement | H145: ='Master 2026'!H145 -> Prathamesh | ... AA145: ='Master 2026'!AA145 -> Andleeb/Thirukumaran
A146: ='Master 2026'!A146 -> 145 | B146: ='Master 2026'!B146 -> India | C146: ='Master 2026'!C146 -> Delivery | D146: ='Master 2026'!D146 -> PS | E146: ='Master 2026'!E146 -> Delivery Manager | F146: ='Master 2026'!F146 -> Kanan | G146: ='Master 2026'!G146 -> Replacement | H146: ='Master 2026'!H146 -> Satyavir/Kishore T | ... AA146: ='Master 2026'!AA146 -> Andleeb
...

Sheet Dashboard
A1: India Joiners Dashboard
A2: FY2026 · Source: Master 2026 (Geo = India, Status = Joined) · Live formulas, auto-updates
A4: Joiners by Location & Quarter
A5: Location | B5: Q1 | C5: Q2 | D5: Q3 | E5: Q4 | F5: Total
